Workbook

Sheet Componentes
A1: Nombre | B1: Descripción | C1: Orden | D1: Instructor (correo, opcional)
A2: Fundamentos de Frontend | B2: HTML, CSS, JavaScript moderno | C2: 1

Sheet Horario 8 semanas
A1: Semana | B1: Día | C1: Fecha | D1: Sesión | E1: Bloque | F1: Horario | G1: Componente | H1: Tema | I1: Contenidos | J1: Horas académicas
A2: 1 | B2: Lunes | C2: =Resumen!$B$2+(A2-1)*7+0 -> 46300 | D2: 1 | E2: 1 | F2: 18:30 – 20:00 | J2: 2
A3: 1 | B3: Lunes | C3: =Resumen!$B$2+(A3-1)*7+0 -> 46300 | D3: 1 | E3: 2 | F3: 20:30 – 22:00 | J3: 2
A4: 1 | B4: Martes | C4: =Resumen!$B$2+(A4-1)*7+1 -> 46301 | D4: 2 | E4: 1 | F4: 18:30 – 20:00 | J4: 2
A5: 1 | B5: Martes | C5: =Resumen!$B$2+(A5-1)*7+1 -> 46301 | D5: 2 | E5: 2 | F5: 20:30 – 22:00 | J5: 2
A6: 1 | B6: Miércoles | C6: =Resumen!$B$2+(A6-1)*7+2 -> 46302 | D6: 3 | E6: 1 | F6: 18:30 – 20:00 | J6: 2
A7: 1 | B7: Miércoles | C7: =Resumen!$B$2+(A7-1)*7+2 -> 46302 | D7: 3 | E7: 2 | F7: 20:30 – 22:00 | J7: 2
A8: 1 | B8: Jueves | C8: =Resumen!$B$2+(A8-1)*7+3 -> 46303 | D8: 4 | E8: 1 | F8: 18:30 – 20:00 | J8: 2
A9: 1 | B9: Jueves | C9: =Resumen!$B$2+(A9-1)*7+3 -> 46303 | D9: 4 | E9: 2 | F9: 20:30 – 22:00 | J9: 2
A10: 1 | B10: Viernes | C10: =Resumen!$B$2+(A10-1)*7+4 -> 46304 | D10: 5 | E10: 1 | F10: 18:30 – 20:00 | J10: 2
A11: 1 | B11: Viernes | C11: =Resumen!$B$2+(A11-1)*7+4 -> 46304 | D11: 5 | E11: 2 | F11: 20:30 – 22:00 | J11: 2
A12: 2 | B12: Lunes | C12: =Resumen!$B$2+(A12-1)*7+0 -> 46307 | D12: 6 | E12: 1 | F12: 18:30 – 20:00 | J12: 2
A13: 2 | B13: Lunes | C13: =Resumen!$B$2+(A13-1)*7+0 -> 46307 | D13: 6 | E13: 2 | F13: 20:30 – 22:00 | J13: 2
A14: 2 | B14: Martes | C14: =Resumen!$B$2+(A14-1)*7+1 -> 46308 | D14: 7 | E14: 1 | F14: 18:30 – 20:00 | J14: 2
A15: 2 | B15: Martes | C15: =Resumen!$B$2+(A15-1)*7+1 -> 46308 | D15: 7 | E15: 2 | F15: 20:30 – 22:00 | J15: 2
A16: 2 | B16: Miércoles | C16: =Resumen!$B$2+(A16-1)*7+2 -> 46309 | D16: 8 | E16: 1 | F16: 18:30 – 20:00 | J16: 2
A17: 2 | B17: Miércoles | C17: =Resumen!$B$2+(A17-1)*7+2 -> 46309 | D17: 8 | E17: 2 | F17: 20:30 – 22:00 | J17: 2
A18: 2 | B18: Jueves | C18: =Resumen!$B$2+(A18-1)*7+3 -> 46310 | D18: 9 | E18: 1 | F18: 18:30 – 20:00 | J18: 2
A19: 2 | B19: Jueves | C19: =Resumen!$B$2+(A19-1)*7+3 -> 46310 | D19: 9 | E19: 2 | F19: 20:30 – 22:00 | J19: 2
A20: 2 | B20: Viernes | C20: =Resumen!$B$2+(A20-1)*7+4 -> 46311 | D20: 10 | E20: 1 | F20: 18:30 – 20:00 | J20: 2
A21: 2 | B21: Viernes | C21: =Resumen!$B$2+(A21-1)*7+4 -> 46311 | D21: 10 | E21: 2 | F21: 20:30 – 22:00 | J21: 2
A22: 3 | B22: Lunes | C22: =Resumen!$B$2+(A22-1)*7+0 -> 46314 | D22: 11 | E22: 1 | F22: 18:30 – 20:00 | J22: 2
A23: 3 | B23: Lunes | C23: =Resumen!$B$2+(A23-1)*7+0 -> 46314 | D23: 11 | E23: 2 | F23: 20:30 – 22:00 | J23: 2
A24: 3 | B24: Martes | C24: =Resumen!$B$2+(A24-1)*7+1 -> 46315 | D24: 12 | E24: 1 | F24: 18:30 – 20:00 | J24: 2
A25: 3 | B25: Martes | C25: =Resumen!$B$2+(A25-1)*7+1 -> 46315 | D25: 12 | E25: 2 | F25: 20:30 – 22:00 | J25: 2
A26: 3 | B26: Miércoles | C26: =Resumen!$B$2+(A26-1)*7+2 -> 46316 | D26: 13 | E26: 1 | F26: 18:30 – 20:00 | J26: 2
A27: 3 | B27: Miércoles | C27: =Resumen!$B$2+(A27-1)*7+2 -> 46316 | D27: 13 | E27: 2 | F27: 20:30 – 22:00 | J27: 2
A28: 3 | B28: Jueves | C28: =Resumen!$B$2+(A28-1)*7+3 -> 46317 | D28: 14 | E28: 1 | F28: 18:30 – 20:00 | J28: 2
A29: 3 | B29: Jueves | C29: =Resumen!$B$2+(A29-1)*7+3 -> 46317 | D29: 14 | E29: 2 | F29: 20:30 – 22:00 | J29: 2
A30: 3 | B30: Viernes | C30: =Resumen!$B$2+(A30-1)*7+4 -> 46318 | D30: 15 | E30: 1 | F30: 18:30 – 20:00 | J30: 2
A31: 3 | B31: Viernes | C31: =Resumen!$B$2+(A31-1)*7+4 -> 46318 | D31: 15 | E31: 2 | F31: 20:30 – 22:00 | J31: 2
A32: 4 | B32: Lunes | C32: =Resumen!$B$2+(A32-1)*7+0 -> 46321 | D32: 16 | E32: 1 | F32: 18:30 – 20:00 | J32: 2
A33: 4 | B33: Lunes | C33: =Resumen!$B$2+(A33-1)*7+0 -> 46321 | D33: 16 | E33: 2 | F33: 20:30 – 22:00 | J33: 2
A34: 4 | B34: Martes | C34: =Resumen!$B$2+(A34-1)*7+1 -> 46322 | D34: 17 | E34: 1 | F34: 18:30 – 20:00 | J34: 2
A35: 4 | B35: Martes | C35: =Resumen!$B$2+(A35-1)*7+1 -> 46322 | D35: 17 | E35: 2 | F35: 20:30 – 22:00 | J35: 2
A36: 4 | B36: Miércoles | C36: =Resumen!$B$2+(A36-1)*7+2 -> 46323 | D36: 18 | E36: 1 | F36: 18:30 – 20:00 | J36: 2
A37: 4 | B37: Miércoles | C37: =Resumen!$B$2+(A37-1)*7+2 -> 46323 | D37: 18 | E37: 2 | F37: 20:30 – 22:00 | J37: 2
A38: 4 | B38: Jueves | C38: =Resumen!$B$2+(A38-1)*7+3 -> 46324 | D38: 19 | E38: 1 | F38: 18:30 – 20:00 | J38: 2
A39: 4 | B39: Jueves | C39: =Resumen!$B$2+(A39-1)*7+3 -> 46324 | D39: 19 | E39: 2 | F39: 20:30 – 22:00 | J39: 2
A40: 4 | B40: Viernes | C40: =Resumen!$B$2+(A40-1)*7+4 -> 46325 | D40: 20 | E40: 1 | F40: 18:30 – 20:00 | J40: 2
...

Sheet Resumen
A1: Parámetros
A2: Fecha de inicio (lunes) | B2: 46300 | C2: ← celdas amarillas editables
A3: Minutos por hora académica | B3: 45
A5: Componente | B5: Orden | C5: Sesiones | D5: Horas académicas | E5: Horas reloj | F5: Semana inicio | G5: Semana fin | H5: Fecha inicio | I5: Fecha fin
A6: Versionamiento de codigo | B6: 1 | C6: =COUNTIFS('Horario 8 semanas'!$G$2:$G$81,A6,'Horario 8 semanas'!$E$2:$E$81,"1") -> 3 | D6: =SUMIFS('Horario 8 semanas'!$J$2:$J$81,'Horario 8 semanas'!$G$2:$G$81,A6) -> 12 | E6: =D6*Resumen!$B$3/60 -> 9 | F6: =_xlfn.MINIFS('Horario 8 semanas'!$A$2:$A$81,'Horario 8 semanas'!$G$2:$G$81,A6) -> 1 | G6: =_xlfn.MAXIFS('Horario 8 semanas'!$A$2:$A$81,'Horario 8 semanas'!$G$2:$G$81,A6) -> 1 | H6: =_xlfn.MINIFS('Horario 8 semanas'!$C$2:$C$81,'Horario 8 semanas'!$G$2:$G$81,A6) -> 46300 | I6: =_xlfn.MAXIFS('Horario 8 semanas'!$C$2:$C$81,'Horario 8 semanas'!$G$2:$G$81,A6) -> 46302
A7: Arquitectura | B7: 2 | C7: =COUNTIFS('Horario 8 semanas'!$G$2:$G$81,A7,'Horario 8 semanas'!$E$2:$E$81,"1") -> 5 | D7: =SUMIFS('Horario 8 semanas'!$J$2:$J$81,'Horario 8 semanas'!$G$2:$G$81,A7) -> 20 | E7: =D7*Resumen!$B$3/60 -> 15 | F7: =_xlfn.MINIFS('Horario 8 semanas'!$A$2:$A$81,'Horario 8 semanas'!$G$2:$G$81,A7) -> 1 | G7: =_xlfn.MAXIFS('Horario 8 semanas'!$A$2:$A$81,'Horario 8 semanas'!$G$2:$G$81,A7) -> 2 | H7: =_xlfn.MINIFS('Horario 8 semanas'!$C$2:$C$81,'Horario 8 semanas'!$G$2:$G$81,A7) -> 46303 | I7: =_xlfn.MAXIFS('Horario 8 semanas'!$C$2:$C$81,'Horario 8 semanas'!$G$2:$G$81,A7) -> 46309
A8: Analisis funcional | B8: 3 | C8: =COUNTIFS('Horario 8 semanas'!$G$2:$G$81,A8,'Horario 8 semanas'!$E$2:$E$81,"1") -> 5 | D8: =SUMIFS('Horario 8 semanas'!$J$2:$J$81,'Horario 8 semanas'!$G$2:$G$81,A8) -> 20 | E8: =D8*Resumen!$B$3/60 -> 15 | F8: =_xlfn.MINIFS('Horario 8 semanas'!$A$2:$A$81,'Horario 8 semanas'!$G$2:$G$81,A8) -> 2 | G8: =_xlfn.MAXIFS('Horario 8 semanas'!$A$2:$A$81,'Horario 8 semanas'!$G$2:$G$81,A8) -> 3 | H8: =_xlfn.MINIFS('Horario 8 semanas'!$C$2:$C$81,'Horario 8 semanas'!$G$2:$G$81,A8) -> 46310 | I8: =_xlfn.MAXIFS('Horario 8 semanas'!$C$2:$C$81,'Horario 8 semanas'!$G$2:$G$81,A8) -> 46316
A9: ViveCoding | B9: 4 | C9: =COUNTIFS('Horario 8 semanas'!$G$2:$G$81,A9,'Horario 8 semanas'!$E$2:$E$81,"1") -> 5 | D9: =SUMIFS('Horario 8 semanas'!$J$2:$J$81,'Horario 8 semanas'!$G$2:$G$81,A9) -> 20 | E9: =D9*Resumen!$B$3/60 -> 15 | F9: =_xlfn.MINIFS('Horario 8 semanas'!$A$2:$A$81,'Horario 8 semanas'!$G$2:$G$81,A9) -> 3 | G9: =_xlfn.MAXIFS('Horario 8 semanas'!$A$2:$A$81,'Horario 8 semanas'!$G$2:$G$81,A9) -> 4 | H9: =_xlfn.MINIFS('Horario 8 semanas'!$C$2:$C$81,'Horario 8 semanas'!$G$2:$G$81,A9) -> 46317 | I9: =_xlfn.MAXIFS('Horario 8 semanas'!$C$2:$C$81,'Horario 8 semanas'!$G$2:$G$81,A9) -> 46323
A10: iA Funcional | B10: 5 | C10: =COUNTIFS('Horario 8 semanas'!$G$2:$G$81,A10,'Horario 8 semanas'!$E$2:$E$81,"1") -> 5 | D10: =SUMIFS('Horario 8 semanas'!$J$2:$J$81,'Horario 8 semanas'!$G$2:$G$81,A10) -> 20 | E10: =D10*Resumen!$B$3/60 -> 15 | F10: =_xlfn.MINIFS('Horario 8 semanas'!$A$2:$A$81,'Horario 8 semanas'!$G$2:$G$81,A10) -> 4 | G10: =_xlfn.MAXIFS('Horario 8 semanas'!$A$2:$A$81,'Horario 8 semanas'!$G$2:$G$81,A10) -> 5 | H10: =_xlfn.MINIFS('Horario 8 semanas'!$C$2:$C$81,'Horario 8 semanas'!$G$2:$G$81,A10) -> 46324 | I10: =_xlfn.MAXIFS('Horario 8 semanas'!$C$2:$C$81,'Horario 8 semanas'!$G$2:$G$81,A10) -> 46330
A11: Base de datos | B11: 6 | C11: =COUNTIFS('Horario 8 semanas'!$G$2:$G$81,A11,'Horario 8 semanas'!$E$2:$E$81,"1") -> 5 | D11: =SUMIFS('Horario 8 semanas'!$J$2:$J$81,'Horario 8 semanas'!$G$2:$G$81,A11) -> 20 | E11: =D11*Resumen!$B$3/60 -> 15 | F11: =_xlfn.MINIFS('Horario 8 semanas'!$A$2:$A$81,'Horario 8 semanas'!$G$2:$G$81,A11) -> 5 | G11: =_xlfn.MAXIFS('Horario 8 semanas'!$A$2:$A$81,'Horario 8 semanas'!$G$2:$G$81,A11) -> 6 | H11: =_xlfn.MINIFS('Horario 8 semanas'!$C$2:$C$81,'Horario 8 semanas'!$G$2:$G$81,A11) -> 46331 | I11: =_xlfn.MAXIFS('Horario 8 semanas'!$C$2:$C$81,'Horario 8 semanas'!$G$2:$G$81,A11) -> 46337
A12: Backend | B12: 7 | C12: =COUNTIFS('Horario 8 semanas'!$G$2:$G$81,A12,'Horario 8 semanas'!$E$2:$E$81,"1") -> 6 | D12: =SUMIFS('Horario 8 semanas'!$J$2:$J$81,'Horario 8 semanas'!$G$2:$G$81,A12) -> 24 | E12: =D12*Resumen!$B$3/60 -> 18 | F12: =_xlfn.MINIFS('Horario 8 semanas'!$A$2:$A$81,'Horario 8 semanas'!$G$2:$G$81,A12) -> 6 | G12: =_xlfn.MAXIFS('Horario 8 semanas'!$A$2:$A$81,'Horario 8 semanas'!$G$2:$G$81,A12) -> 7 | H12: =_xlfn.MINIFS('Horario 8 semanas'!$C$2:$C$81,'Horario 8 semanas'!$G$2:$G$81,A12) -> 46338 | I12: =_xlfn.MAXIFS('Horario 8 semanas'!$C$2:$C$81,'Horario 8 semanas'!$G$2:$G$81,A12) -> 46345
A13: Frontend | B13: 8 | C13: =COUNTIFS('Horario 8 semanas'!$G$2:$G$81,A13,'Horario 8 semanas'!$E$2:$E$81,"1") -> 6 | D13: =SUMIFS('Horario 8 semanas'!$J$2:$J$81,'Horario 8 semanas'!$G$2:$G$81,A13) -> 24 | E13: =D13*Resumen!$B$3/60 -> 18 | F13: =_xlfn.MINIFS('Horario 8 semanas'!$A$2:$A$81,'Horario 8 semanas'!$G$2:$G$81,A13) -> 7 | G13: =_xlfn.MAXIFS('Horario 8 semanas'!$A$2:$A$81,'Horario 8 semanas'!$G$2:$G$81,A13) -> 8 | H13: =_xlfn.MINIFS('Horario 8 semanas'!$C$2:$C$81,'Horario 8 semanas'!$G$2:$G$81,A13) -> 46346 | I13: =_xlfn.MAXIFS('Horario 8 semanas'!$C$2:$C$81,'Horario 8 semanas'!$G$2:$G$81,A13) -> 46353
A14: Total | C14: =SUM(C6:C13) -> 40 | D14: =SUM(D6:D13) -> 160 | E14: =SUM(E6:E13) -> 120
A16: Notas:
A17: • Clases de lunes a viernes, 18:30–22:00: 2 bloques de 2 horas académicas con receso de 20:00 a 20:30.
A18: • 40 sesiones / 80 bloques. Los componentes van en el orden de la hoja 'Componentes'; Backend y Frontend reciben 6 sesiones y Versionamiento 3 por su mayor/menor volumen.
A19: • Las fechas no descuentan feriados: si alguno cae dentro del ciclo, mover los temas de esa sesión.
